Workbook

Sheet Lead_Master
A1: Lead ID | B1: Lead Name | C1: Email | D1: Phone | E1: College | F1: Course | G1: Graduation Year | H1: Interested Program | I1: Preferred Language | J1: Lead Date
A2: LEAD0001 | B2: Shreya Verma | C2: lead0001@example.com | D2: 9685582861 | E2: Amity University | F2: MCA | G2: 2028 | H2: Data Analytics | I2: English | J2: 46207
A3: LEAD0002 | B3: Riya Gupta | C3: lead0002@example.com | D3: 9550455977 | E3: GL Bajaj Institute | F3: B.Sc | G3: 2027 | H3: Cloud Computing | I3: English | J3: 46268
A4: LEAD0003 | B4: Ishita Mehta | C4: lead0003@example.com | D4: 9485451171 | E4: Chandigarh University | F4: MCA | G4: 2027 | H4: Cloud Computing | I4: English | J4: 46247
A5: LEAD0004 | B5: Abhishek Verma | C5: lead0004@example.com | D5: 9488302652 | E5: IMS Noida | F5: BBA | G5: 2025 | H5: Data Analytics | I5: Hinglish | J5: 46252
A6: LEAD0005 | B6: Tanya Kumar | C6: lead0005@example.com | D6: 9274648506 | E6: Chandigarh University | F6: B.Tech | G6: 2026 | H6: Cyber Security | I6: Hindi | J6: 46214
A7: LEAD0006 | B7: Aman Jain | C7: lead0006@example.com | D7: 9335809993 | E7: IIMT University | F7: B.Tech | G7: 2025 | H7: Digital Marketing | I7: English | J7: 46225
A8: LEAD0007 | B8: Arjun Kumar | C8: lead0007@example.com | D8: 9803771909 | E8: KIET Group of Institutions | F8: B.Sc | G8: 2028 | H8: Digital Marketing | I8: Hindi | J8: 46212
A9: LEAD0008 | B9: Karan Agarwal | C9: lead0008@example.com | D9: 9647099690 | E9: KIET Group of Institutions | F9: BCA | G9: 2025 | H9: Cloud Computing | I9: English | J9: 46275
A10: LEAD0009 | B10: Shreya Singh | C10: lead0009@example.com | D10: 9112327652 | E10: IIMT University | F10: MBA | G10: 2025 | H10: Cyber Security | I10: Hinglish | J10: 46291
A11: LEAD0010 | B11: Tanya Jain | C11: lead0010@example.com | D11: 9875340444 | E11: Graphic Era University | F11: B.Tech | G11: 2026 | H11: AI & Machine Learning | I11: English | J11: 46247
A12: LEAD0011 | B12: Mehak Jain | C12: lead0011@example.com | D12: 9936043811 | E12: Noida International University | F12: BCA | G12: 2027 | H12: Business Analytics | I12: English | J12: 46268
A13: LEAD0012 | B13: Harsh Patel | C13: lead0012@example.com | D13: 9191969690 | E13: Graphic Era University | F13: B.Sc | G13: 2025 | H13: Cloud Computing | I13: Hinglish | J13: 46243
... A301: LEAD0300 | B301: Ananya Rathore | C301: lead0300@example.com | D301: 9138474240 | E301: Noida International University | F301: MCA | G301: 2025 | H301: Cloud Computing | I301: English | J301: 46267

Sheet Interaction_Log
A1: Interaction ID | B1: Lead ID | C1: Date | D1: Interaction Type | E1: Outcome | F1: Remarks | G1: Next Follow-up | H1: Data Check
A2: INT00001 | B2: LEAD0001 | C2: 46211 | D2: Call | E2: DNP | H2: =IF(C2>CRM_Dashboard!$B$3,"Future-dated",IF(AND(B2=B1,C2<C1),"Date out of sequence",IF(AND(G2<>"",G2<=C2),"Follow-up not after interaction","")))
A3: INT00002 | B3: LEAD0001 | C3: 46211 | D3: Call | E3: DNP | H3: =IF(C3>CRM_Dashboard!$B$3,"Future-dated",IF(AND(B3=B2,C3<C2),"Date out of sequence",IF(AND(G3<>"",G3<=C3),"Follow-up not after interaction","")))
A4: INT00003 | B4: LEAD0001 | C4: 46210 | D4: Call | E4: DNP | F4: Asked for callback | H4: =IF(C4>CRM_Dashboard!$B$3,"Future-dated",IF(AND(B4=B3,C4<C3),"Date out of sequence",IF(AND(G4<>"",G4<=C4),"Follow-up not after interaction",""))) -> Date out of sequence
A5: INT00004 | B5: LEAD0002 | C5: 46271 | D5: Call | E5: Follow Up | F5: Details shared | G5: 46277 | H5: =IF(C5>CRM_Dashboard!$B$3,"Future-dated",IF(AND(B5=B4,C5<C4),"Date out of sequence",IF(AND(G5<>"",G5<=C5),"Follow-up not after interaction","")))
A6: INT00005 | B6: LEAD0003 | C6: 46249 | D6: Call | E6: DNP | H6: =IF(C6>CRM_Dashboard!$B$3,"Future-dated",IF(AND(B6=B5,C6<C5),"Date out of sequence",IF(AND(G6<>"",G6<=C6),"Follow-up not after interaction","")))
A7: INT00006 | B7: LEAD0003 | C7: 46249 | D7: Call | E7: Call Cut | H7: =IF(C7>CRM_Dashboard!$B$3,"Future-dated",IF(AND(B7=B6,C7<C6),"Date out of sequence",IF(AND(G7<>"",G7<=C7),"Follow-up not after interaction","")))
A8: INT00007 | B8: LEAD0003 | C8: 46247 | D8: Call | E8: Call Back Later | F8: Follow-up required | G8: 46249 | H8: =IF(C8>CRM_Dashboard!$B$3,"Future-dated",IF(AND(B8=B7,C8<C7),"Date out of sequence",IF(AND(G8<>"",G8<=C8),"Follow-up not after interaction",""))) -> Date out of sequence
A9: INT00008 | B9: LEAD0004 | C9: 46253 | D9: Call | E9: Details Sent | F9: No response | G9: 46262 | H9: =IF(C9>CRM_Dashboard!$B$3,"Future-dated",IF(AND(B9=B8,C9<C8),"Date out of sequence",IF(AND(G9<>"",G9<=C9),"Follow-up not after interaction","")))
A10: INT00009 | B10: LEAD0005 | C10: 46217 | D10: Call | E10: Switch Off | H10: =IF(C10>CRM_Dashboard!$B$3,"Future-dated",IF(AND(B10=B9,C10<C9),"Date out of sequence",IF(AND(G10<>"",G10<=C10),"Follow-up not after interaction","")))
A11: INT00010 | B11: LEAD0005 | C11: 46216 | D11: Call | E11: Details Sent | F11: Asked for callback | G11: 46220 | H11: =IF(C11>CRM_Dashboard!$B$3,"Future-dated",IF(AND(B11=B10,C11<C10),"Date out of sequence",IF(AND(G11<>"",G11<=C11),"Follow-up not after interaction",""))) -> Date out of sequence
A12: INT00011 | B12: LEAD0006 | C12: 46229 | D12: Call | E12: DNP | H12: =IF(C12>CRM_Dashboard!$B$3,"Future-dated",IF(AND(B12=B11,C12<C11),"Date out of sequence",IF(AND(G12<>"",G12<=C12),"Follow-up not after interaction","")))
A13: INT00012 | B13: LEAD0006 | C13: 46231 | D13: Call | E13: Call Back Later | F13: Requested course information | G13: 46234 | H13: =IF(C13>CRM_Dashboard!$B$3,"Future-dated",IF(AND(B13=B12,C13<C12),"Date out of sequence",IF(AND(G13<>"",G13<=C13),"Follow-up not after interaction","")))
A14: INT00013 | B14: LEAD0007 | C14: 46216 | D14: Call | E14: Paid | H14: =IF(C14>CRM_Dashboard!$B$3,"Future-dated",IF(AND(B14=B13,C14<C13),"Date out of sequence",IF(AND(G14<>"",G14<=C14),"Follow-up not after interaction","")))
A15: INT00014 | B15: LEAD0007 | C15: 46216 | D15: Call | E15: Follow Up | F15: Details shared | G15: 46216 | H15: =IF(C15>CRM_Dashboard!$B$3,"Future-dated",IF(AND(B15=B14,C15<C14),"Date out of sequence",IF(AND(G15<>"",G15<=C15),"Follow-up not after interaction",""))) -> Follow-up not after interaction
A16: INT00015 | B16: LEAD0008 | C16: 46278 | D16: Call | E16: Not Interested | H16: =IF(C16>CRM_Dashboard!$B$3,"Future-dated",IF(AND(B16=B15,C16<C15),"Date out of sequence",IF(AND(G16<>"",G16<=C16),"Follow-up not after interaction","")))
A17: INT00016 | B17: LEAD0008 | C17: 46280 | D17: Call | E17: Details Sent | H17: =IF(C17>CRM_Dashboard!$B$3,"Future-dated",IF(AND(B17=B16,C17<C16),"Date out of sequence",IF(AND(G17<>"",G17<=C17),"Follow-up not after interaction","")))
A18: INT00017 | B18: LEAD0008 | C18: 46280 | D18: Call | E18: Follow Up | F18: Details shared | G18: 46278 | H18: =IF(C18>CRM_Dashboard!$B$3,"Future-dated",IF(AND(B18=B17,C18<C17),"Date out of sequence",IF(AND(G18<>"",G18<=C18),"Follow-up not after interaction",""))) -> Follow-up not after interaction
A19: INT00018 | B19: LEAD0009 | C19: 46294 | D19: Call | E19: Follow Up | H19: =IF(C19>CRM_Dashboard!$B$3,"Future-dated",IF(AND(B19=B18,C19<C18),"Date out of sequence",IF(AND(G19<>"",G19<=C19),"Follow-up not after interaction","")))
A20: INT00019 | B20: LEAD0009 | C20: 46291 | D20: Call | E20: Details Sent | H20: =IF(C20>CRM_Dashboard!$B$3,"Future-dated",IF(AND(B20=B19,C20<C19),"Date out of sequence",IF(AND(G20<>"",G20<=C20),"Follow-up not after interaction",""))) -> Date out of sequence
A21: INT00020 | B21: LEAD0009 | C21: 46292 | D21: Call | E21: Follow Up | H21: =IF(C21>CRM_Dashboard!$B$3,"Future-dated",IF(AND(B21=B20,C21<C20),"Date out of sequence",IF(AND(G21<>"",G21<=C21),"Follow-up not after interaction","")))
A22: INT00021 | B22: LEAD0009 | C22: 46301 | D22: Call | E22: Details Sent | F22: Not interested currently | G22: 46300 | H22: =IF(C22>CRM_Dashboard!$B$3,"Future-dated",IF(AND(B22=B21,C22<C21),"Date out of sequence",IF(AND(G22<>"",G22<=C22),"Follow-up not after interaction",""))) -> Future-dated
A23: INT00022 | B23: LEAD0010 | C23: 46248 | D23: Call | E23: Call Back Later | F23: Not interested currently | G23: 46248 | H23: =IF(C23>CRM_Dashboard!$B$3,"Future-dated",IF(AND(B23=B22,C23<C22),"Date out of sequence",IF(AND(G23<>"",G23<=C23),"Follow-up not after interaction",""))) -> Follow-up not after interaction
A24: INT00023 | B24: LEAD0011 | C24: 46268 | D24: Call | E24: DNP | H24: =IF(C24>CRM_Dashboard!$B$3,"Future-dated",IF(AND(B24=B23,C24<C23),"Date out of sequence",IF(AND(G24<>"",G24<=C24),"Follow-up not after interaction","")))
A25: INT00024 | B25: LEAD0011 | C25: 46270 | D25: Call | E25: Not Interested | F25: Asked for callback | H25: =IF(C25>CRM_Dashboard!$B$3,"Future-dated",IF(AND(B25=B24,C25<C24),"Date out of sequence",IF(AND(G25<>"",G25<=C25),"Follow-up not after interaction","")))
A26: INT00025 | B26: LEAD0012 | C26: 46245 | D26: Call | E26: DNP | H26: =IF(C26>CRM_Dashboard!$B$3,"Future-dated",IF(AND(B26=B25,C26<C25),"Date out of sequence",IF(AND(G26<>"",G26<=C26),"Follow-up not after interaction","")))
A27: INT00026 | B27: LEAD0012 | C27: 46249 | D27: Call | E27: Switch Off | F27: Details shared | H27: =IF(C27>CRM_Dashboard!$B$3,"Future-dated",IF(AND(B27=B26,C27<C26),"Date out of sequence",IF(AND(G27<>"",G27<=C27),"Follow-up not after interaction","")))
A28: INT00027 | B28: LEAD0013 | C28: 46266 | D28: Call | E28: DNP | H28: =IF(C28>CRM_Dashboard!$B$3,"Future-dated",IF(AND(B28=B27,C28<C27),"Date out of sequence",IF(AND(G28<>"",G28<=C28),"Follow-up not after interaction","")))
A29: INT00028 | B29: LEAD0013 | C29: 46268 | D29: Call | E29: Switch Off | F29: Number unreachable | H29: =IF(C29>CRM_Dashboard!$B$3,"Future-dated",IF(AND(B29=B28,C29<C28),"Date out of sequence",IF(AND(G29<>"",G29<=C29),"Follow-up not after interaction","")))
A30: INT00029 | B30: LEAD0014 | C30: 46255 | D30: Call | E30: Wrong Number | H30: =IF(C30>CRM_Dashboard!$B$3,"Future-dated",IF(AND(B30=B29,C30<C29),"Date out of sequence",IF(AND(G30<>"",G30<=C30),"Follow-up not after interaction","")))
A31: INT00030 | B31: LEAD0014 | C31: 46253 | D31: Call | E31: Details Sent | H31: =IF(C31>CRM_Dashboard!$B$3,"Future-dated",IF(AND(B31=B30,C31<C30),"Date out of sequence",IF(AND(G31<>"",G31<=C31),"Follow-up not after interaction",""))) -> Date out of sequence
A32: INT00031 | B32: LEAD0014 | C32: 46252 | D32: Call | E32: DNP | H32: =IF(C32>CRM_Dashboard!$B$3,"Future-dated",IF(AND(B32=B31,C32<C31),"Date out of sequence",IF(AND(G32<>"",G32<=C32),"Follow-up not after interaction",""))) -> Date out of sequence
A33: INT00032 | B33: LEAD0014 | C33: 46251 | D33: Call | E33: Paid | F33: Interested, needs more details | H33: =IF(C33>CRM_Dashboard!$B$3,"Future-dated",IF(AND(B33=B32,C33<C32),"Date out of sequence",IF(AND(G33<>"",G33<=C33),"Follow-up not after interaction",""))) -> Date out of sequence
A34: INT00033 | B34: LEAD0015 | C34: 46209 | D34: Call | E34: DNP | H34: =IF(C34>CRM_Dashboard!$B$3,"Future-dated",IF(AND(B34=B33,C34<C33),"Date out of sequence",IF(AND(G34<>"",G34<=C34),"Follow-up not after interaction","")))
A35: INT00034 | B35: LEAD0015 | C35: 46211 | D35: Call | E35: DNP | H35: =IF(C35>CRM_Dashboard!$B$3,"Future-dated",IF(AND(B35=B34,C35<C34),"Date out of sequence",IF(AND(G35<>"",G35<=C35),"Follow-up not after interaction","")))
A36: INT00035 | B36: LEAD0015 | C36: 46210 | D36: Call | E36: Follow Up | F36: Number unreachable | G36: 46211 | H36: =IF(C36>CRM_Dashboard!$B$3,"Future-dated",IF(AND(B36=B35,C36<C35),"Date out of sequence",IF(AND(G36<>"",G36<=C36),"Follow-up not after interaction",""))) -> Date out of sequence
A37: INT00036 | B37: LEAD0016 | C37: 46219 | D37: Call | E37: Call Back Later | H37: =IF(C37>CRM_Dashboard!$B$3,"Future-dated",IF(AND(B37=B36,C37<C36),"Date out of sequence",IF(AND(G37<>"",G37<=C37),"Follow-up not after interaction","")))
A38: INT00037 | B38: LEAD0016 | C38: 46216 | D38: Call | E38: Details Sent | H38: =IF(C38>CRM_Dashboard!$B$3,"Future-dated",IF(AND(B38=B37,C38<C37),"Date out of sequence",IF(AND(G38<>"",G38<=C38),"Follow-up not after interaction",""))) -> Date out of sequence
A39: INT00038 | B39: LEAD0016 | C39: 46220 | D39: Call | E39: Switch Off | H39: =IF(C39>CRM_Dashboard!$B$3,"Future-dated",IF(AND(B39=B38,C39<C38),"Date out of sequence",IF(AND(G39<>"",G39<=C39),"Follow-up not after interaction","")))
A40: INT00039 | B40: LEAD0016 | C40: 46225 | D40: Call | E40: DNP | F40: Asked for callback | H40: =IF(C40>CRM_Dashboard!$B$3,"Future-dated",IF(AND(B40=B39,C40<C39),"Date out of sequence",IF(AND(G40<>"",G40<=C40),"Follow-up not after interaction","")))
...

Sheet Follow_Up_Tracker
A1: Lead ID | B1: Lead Name | C1: Last Interaction | D1: Current Status | E1: Next Follow-up | F1: Priority | G1: Action | H1: Due Status | I1: Interactions | J1: Details Sent (Ever) | K1: Data Flag
A2: LEAD0001 | B2: =IFERROR(INDEX(Lead_Master!$B$2:$B$1000,MATCH($A2,Lead_Master!$A$2:$A$1000,0)),"") -> Shreya Verma | C2: =IFERROR(LOOKUP(2,1/(Interaction_Log!$B$2:$B$3000=$A2),Interaction_Log!$E$2:$E$3000),"No contact") -> DNP | D2: =IFERROR(INDEX(Lists!$B$2:$B$12,MATCH($C2,Lists!$A$2:$A$12,0)),"Unmapped") -> Pending | E2: =IFERROR(LOOKUP(2,1/((Interaction_Log!$B$2:$B$3000=$A2)*(Interaction_Log!$G$2:$G$3000<>"")),Interaction_Log!$G$2:$G$3000),"") | F2: =IFERROR(INDEX(Lists!$C$2:$C$12,MATCH($C2,Lists!$A$2:$A$12,0)),"") -> Low | G2: =IFERROR(INDEX(Lists!$D$2:$D$12,MATCH($C2,Lists!$A$2:$A$12,0)),"") -> Retry | H2: =IF(OR($D2="Converted",$D2="Closed"),"—",IF($E2="","Not Scheduled",IF($E2<CRM_Dashboard!$B$3,"Overdue",IF($E2=CRM_Dashboard!$B$3,"Due Today","Upcoming")))) -> Not Scheduled | I2: =COUNTIF(Interaction_Log!$B$2:$B$3000,$A2) -> 3 | J2: =IF(COUNTIFS(Interaction_Log!$B$2:$B$3000,$A2,Interaction_Log!$E$2:$E$3000,"Details Sent")>0,"Yes","No") -> No | K2: =IF(AND(COUNTIFS(Interaction_Log!$B$2:$B$3000,$A2,Interaction_Log!$E$2:$E$3000,"Paid")>0,$C2<>"Paid"),"Paid then re-opened","")
A3: LEAD0002 | B3: =IFERROR(INDEX(Lead_Master!$B$2:$B$1000,MATCH($A3,Lead_Master!$A$2:$A$1000,0)),"") -> Riya Gupta | C3: =IFERROR(LOOKUP(2,1/(Interaction_Log!$B$2:$B$3000=$A3),Interaction_Log!$E$2:$E$3000),"No contact") -> Follow Up | D3: =IFERROR(INDEX(Lists!$B$2:$B$12,MATCH($C3,Lists!$A$2:$A$12,0)),"Unmapped") -> Follow Up | E3: =IFERROR(LOOKUP(2,1/((Interaction_Log!$B$2:$B$3000=$A3)*(Interaction_Log!$G$2:$G$3000<>"")),Interaction_Log!$G$2:$G$3000),"") -> 46277 | F3: =IFERROR(INDEX(Lists!$C$2:$C$12,MATCH($C3,Lists!$A$2:$A$12,0)),"") -> High | G3: =IFERROR(INDEX(Lists!$D$2:$D$12,MATCH($C3,Lists!$A$2:$A$12,0)),"") -> Call | H3: =IF(OR($D3="Converted",$D3="Closed"),"—",IF($E3="","Not Scheduled",IF($E3<CRM_Dashboard!$B$3,"Overdue",IF($E3=CRM_Dashboard!$B$3,"Due Today","Upcoming")))) -> Overdue | I3: =COUNTIF(Interaction_Log!$B$2:$B$3000,$A3) -> 1 | J3: =IF(COUNTIFS(Interaction_Log!$B$2:$B$3000,$A3,Interaction_Log!$E$2:$E$3000,"Details Sent")>0,"Yes","No") -> No | K3: =IF(AND(COUNTIFS(Interaction_Log!$B$2:$B$3000,$A3,Interaction_Log!$E$2:$E$3000,"Paid")>0,$C3<>"Paid"),"Paid then re-opened","")
A4: LEAD0003 | B4: =IFERROR(INDEX(Lead_Master!$B$2:$B$1000,MATCH($A4,Lead_Master!$A$2:$A$1000,0)),"") -> Ishita Mehta | C4: =IFERROR(LOOKUP(2,1/(Interaction_Log!$B$2:$B$3000=$A4),Interaction_Log!$E$2:$E$3000),"No contact") -> Call Back Later | D4: =IFERROR(INDEX(Lists!$B$2:$B$12,MATCH($C4,Lists!$A$2:$A$12,0)),"Unmapped") -> Pending | E4: =IFERROR(LOOKUP(2,1/((Interaction_Log!$B$2:$B$3000=$A4)*(Interaction_Log!$G$2:$G$3000<>"")),Interaction_Log!$G$2:$G$3000),"") -> 46249 | F4: =IFERROR(INDEX(Lists!$C$2:$C$12,MATCH($C4,Lists!$A$2:$A$12,0)),"") -> Medium | G4: =IFERROR(INDEX(Lists!$D$2:$D$12,MATCH($C4,Lists!$A$2:$A$12,0)),"") -> Call | H4: =IF(OR($D4="Converted",$D4="Closed"),"—",IF($E4="","Not Scheduled",IF($E4<CRM_Dashboard!$B$3,"Overdue",IF($E4=CRM_Dashboard!$B$3,"Due Today","Upcoming")))) -> Overdue | I4: =COUNTIF(Interaction_Log!$B$2:$B$3000,$A4) -> 3 | J4: =IF(COUNTIFS(Interaction_Log!$B$2:$B$3000,$A4,Interaction_Log!$E$2:$E$3000,"Details Sent")>0,"Yes","No") -> No | K4: =IF(AND(COUNTIFS(Interaction_Log!$B$2:$B$3000,$A4,Interaction_Log!$E$2:$E$3000,"Paid")>0,$C4<>"Paid"),"Paid then re-opened","")
A5: LEAD0004 | B5: =IFERROR(INDEX(Lead_Master!$B$2:$B$1000,MATCH($A5,Lead_Master!$A$2:$A$1000,0)),"") -> Abhishek Verma | C5: =IFERROR(LOOKUP(2,1/(Interaction_Log!$B$2:$B$3000=$A5),Interaction_Log!$E$2:$E$3000),"No contact") -> Details Sent | D5: =IFERROR(INDEX(Lists!$B$2:$B$12,MATCH($C5,Lists!$A$2:$A$12,0)),"Unmapped") -> Follow Up | E5: =IFERROR(LOOKUP(2,1/((Interaction_Log!$B$2:$B$3000=$A5)*(Interaction_Log!$G$2:$G$3000<>"")),Interaction_Log!$G$2:$G$3000),"") -> 46262 | F5: =IFERROR(INDEX(Lists!$C$2:$C$12,MATCH($C5,Lists!$A$2:$A$12,0)),"") -> High | G5: =IFERROR(INDEX(Lists!$D$2:$D$12,MATCH($C5,Lists!$A$2:$A$12,0)),"") -> Call | H5: =IF(OR($D5="Converted",$D5="Closed"),"—",IF($E5="","Not Scheduled",IF($E5<CRM_Dashboard!$B$3,"Overdue",IF($E5=CRM_Dashboard!$B$3,"Due Today","Upcoming")))) -> Overdue | I5: =COUNTIF(Interaction_Log!$B$2:$B$3000,$A5) -> 1 | J5: =IF(COUNTIFS(Interaction_Log!$B$2:$B$3000,$A5,Interaction_Log!$E$2:$E$3000,"Details Sent")>0,"Yes","No") -> Yes | K5: =IF(AND(COUNTIFS(Interaction_Log!$B$2:$B$3000,$A5,Interaction_Log!$E$2:$E$3000,"Paid")>0,$C5<>"Paid"),"Paid then re-opened","")
A6: LEAD0005 | B6: =IFERROR(INDEX(Lead_Master!$B$2:$B$1000,MATCH($A6,Lead_Master!$A$2:$A$1000,0)),"") -> Tanya Kumar | C6: =IFERROR(LOOKUP(2,1/(Interaction_Log!$B$2:$B$3000=$A6),Interaction_Log!$E$2:$E$3000),"No contact") -> Details Sent | D6: =IFERROR(INDEX(Lists!$B$2:$B$12,MATCH($C6,Lists!$A$2:$A$12,0)),"Unmapped") -> Follow Up | E6: =IFERROR(LOOKUP(2,1/((Interaction_Log!$B$2:$B$3000=$A6)*(Interaction_Log!$G$2:$G$3000<>"")),Interaction_Log!$G$2:$G$3000),"") -> 46220 | F6: =IFERROR(INDEX(Lists!$C$2:$C$12,MATCH($C6,Lists!$A$2:$A$12,0)),"") -> High | G6: =IFERROR(INDEX(Lists!$D$2:$D$12,MATCH($C6,Lists!$A$2:$A$12,0)),"") -> Call | H6: =IF(OR($D6="Converted",$D6="Closed"),"—",IF($E6="","Not Scheduled",IF($E6<CRM_Dashboard!$B$3,"Overdue",IF($E6=CRM_Dashboard!$B$3,"Due Today","Upcoming")))) -> Overdue | I6: =COUNTIF(Interaction_Log!$B$2:$B$3000,$A6) -> 2 | J6: =IF(COUNTIFS(Interaction_Log!$B$2:$B$3000,$A6,Interaction_Log!$E$2:$E$3000,"Details Sent")>0,"Yes","No") -> Yes | K6: =IF(AND(COUNTIFS(Interaction_Log!$B$2:$B$3000,$A6,Interaction_Log!$E$2:$E$3000,"Paid")>0,$C6<>"Paid"),"Paid then re-opened","")
A7: LEAD0006 | B7: =IFERROR(INDEX(Lead_Master!$B$2:$B$1000,MATCH($A7,Lead_Master!$A$2:$A$1000,0)),"") -> Aman Jain | C7: =IFERROR(LOOKUP(2,1/(Interaction_Log!$B$2:$B$3000=$A7),Interaction_Log!$E$2:$E$3000),"No contact") -> Call Back Later | D7: =IFERROR(INDEX(Lists!$B$2:$B$12,MATCH($C7,Lists!$A$2:$A$12,0)),"Unmapped") -> Pending | E7: =IFERROR(LOOKUP(2,1/((Interaction_Log!$B$2:$B$3000=$A7)*(Interaction_Log!$G$2:$G$3000<>"")),Interaction_Log!$G$2:$G$3000),"") -> 46234 | F7: =IFERROR(INDEX(Lists!$C$2:$C$12,MATCH($C7,Lists!$A$2:$A$12,0)),"") -> Medium | G7: =IFERROR(INDEX(Lists!$D$2:$D$12,MATCH($C7,Lists!$A$2:$A$12,0)),"") -> Call | H7: =IF(OR($D7="Converted",$D7="Closed"),"—",IF($E7="","Not Scheduled",IF($E7<CRM_Dashboard!$B$3,"Overdue",IF($E7=CRM_Dashboard!$B$3,"Due Today","Upcoming")))) -> Overdue | I7: =COUNTIF(Interaction_Log!$B$2:$B$3000,$A7) -> 2 | J7: =IF(COUNTIFS(Interaction_Log!$B$2:$B$3000,$A7,Interaction_Log!$E$2:$E$3000,"Details Sent")>0,"Yes","No") -> No | K7: =IF(AND(COUNTIFS(Interaction_Log!$B$2:$B$3000,$A7,Interaction_Log!$E$2:$E$3000,"Paid")>0,$C7<>"Paid"),"Paid then re-opened","")
A8: LEAD0007 | B8: =IFERROR(INDEX(Lead_Master!$B$2:$B$1000,MATCH($A8,Lead_Master!$A$2:$A$1000,0)),"") -> Arjun Kumar | C8: =IFERROR(LOOKUP(2,1/(Interaction_Log!$B$2:$B$3000=$A8),Interaction_Log!$E$2:$E$3000),"No contact") -> Follow Up | D8: =IFERROR(INDEX(Lists!$B$2:$B$12,MATCH($C8,Lists!$A$2:$A$12,0)),"Unmapped") -> Follow Up | E8: =IFERROR(LOOKUP(2,1/((Interaction_Log!$B$2:$B$3000=$A8)*(Interaction_Log!$G$2:$G$3000<>"")),Interaction_Log!$G$2:$G$3000),"") -> 46216 | F8: =IFERROR(INDEX(Lists!$C$2:$C$12,MATCH($C8,Lists!$A$2:$A$12,0)),"") -> High | G8: =IFERROR(INDEX(Lists!$D$2:$D$12,MATCH($C8,Lists!$A$2:$A$12,0)),"") -> Call | H8: =IF(OR($D8="Converted",$D8="Closed"),"—",IF($E8="","Not Scheduled",IF($E8<CRM_Dashboard!$B$3,"Overdue",IF($E8=CRM_Dashboard!$B$3,"Due Today","Upcoming")))) -> Overdue | I8: =COUNTIF(Interaction_Log!$B$2:$B$3000,$A8) -> 2 | J8: =IF(COUNTIFS(Interaction_Log!$B$2:$B$3000,$A8,Interaction_Log!$E$2:$E$3000,"Details Sent")>0,"Yes","No") -> No | K8: =IF(AND(COUNTIFS(Interaction_Log!$B$2:$B$3000,$A8,Interaction_Log!$E$2:$E$3000,"Paid")>0,$C8<>"Paid"),"Paid then re-opened","") -> Paid then re-opened
A9: LEAD0008 | B9: =IFERROR(INDEX(Lead_Master!$B$2:$B$1000,MATCH($A9,Lead_Master!$A$2:$A$1000,0)),"") -> Karan Agarwal | C9: =IFERROR(LOOKUP(2,1/(Interaction_Log!$B$2:$B$3000=$A9),Interaction_Log!$E$2:$E$3000),"No contact") -> Follow Up | D9: =IFERROR(INDEX(Lists!$B$2:$B$12,MATCH($C9,Lists!$A$2:$A$12,0)),"Unmapped") -> Follow Up | E9: =IFERROR(LOOKUP(2,1/((Interaction_Log!$B$2:$B$3000=$A9)*(Interaction_Log!$G$2:$G$3000<>"")),Interaction_Log!$G$2:$G$3000),"") -> 46278 | F9: =IFERROR(INDEX(Lists!$C$2:$C$12,MATCH($C9,Lists!$A$2:$A$12,0)),"") -> High | G9: =IFERROR(INDEX(Lists!$D$2:$D$12,MATCH($C9,Lists!$A$2:$A$12,0)),"") -> Call | H9: =IF(OR($D9="Converted",$D9="Closed"),"—",IF($E9="","Not Scheduled",IF($E9<CRM_Dashboard!$B$3,"Overdue",IF($E9=CRM_Dashboard!$B$3,"Due Today","Upcoming")))) -> Overdue | I9: =COUNTIF(Interaction_Log!$B$2:$B$3000,$A9) -> 3 | J9: =IF(COUNTIFS(Interaction_Log!$B$2:$B$3000,$A9,Interaction_Log!$E$2:$E$3000,"Details Sent")>0,"Yes","No") -> Yes | K9: =IF(AND(COUNTIFS(Interaction_Log!$B$2:$B$3000,$A9,Interaction_Log!$E$2:$E$3000,"Paid")>0,$C9<>"Paid"),"Paid then re-opened","")
A10: LEAD0009 | B10: =IFERROR(INDEX(Lead_Master!$B$2:$B$1000,MATCH($A10,Lead_Master!$A$2:$A$1000,0)),"") -> Shreya Singh | C10: =IFERROR(LOOKUP(2,1/(Interaction_Log!$B$2:$B$3000=$A10),Interaction_Log!$E$2:$E$3000),"No contact") -> Details Sent | D10: =IFERROR(INDEX(Lists!$B$2:$B$12,MATCH($C10,Lists!$A$2:$A$12,0)),"Unmapped") -> Follow Up | E10: =IFERROR(LOOKUP(2,1/((Interaction_Log!$B$2:$B$3000=$A10)*(Interaction_Log!$G$2:$G$3000<>"")),Interaction_Log!$G$2:$G$3000),"") -> 46300 | F10: =IFERROR(INDEX(Lists!$C$2:$C$12,MATCH($C10,Lists!$A$2:$A$12,0)),"") -> High | G10: =IFERROR(INDEX(Lists!$D$2:$D$12,MATCH($C10,Lists!$A$2:$A$12,0)),"") -> Call | H10: =IF(OR($D10="Converted",$D10="Closed"),"—",IF($E10="","Not Scheduled",IF($E10<CRM_Dashboard!$B$3,"Overdue",IF($E10=CRM_Dashboard!$B$3,"Due Today","Upcoming")))) -> Upcoming | I10: =COUNTIF(Interaction_Log!$B$2:$B$3000,$A10) -> 4 | J10: =IF(COUNTIFS(Interaction_Log!$B$2:$B$3000,$A10,Interaction_Log!$E$2:$E$3000,"Details Sent")>0,"Yes","No") -> Yes | K10: =IF(AND(COUNTIFS(Interaction_Log!$B$2:$B$3000,$A10,Interaction_Log!$E$2:$E$3000,"Paid")>0,$C10<>"Paid"),"Paid then re-opened","")
A11: LEAD0010 | B11: =IFERROR(INDEX(Lead_Master!$B$2:$B$1000,MATCH($A11,Lead_Master!$A$2:$A$1000,0)),"") -> Tanya Jain | C11: =IFERROR(LOOKUP(2,1/(Interaction_Log!$B$2:$B$3000=$A11),Interaction_Log!$E$2:$E$3000),"No contact") -> Call Back Later | D11: =IFERROR(INDEX(Lists!$B$2:$B$12,MATCH($C11,Lists!$A$2:$A$12,0)),"Unmapped") -> Pending | E11: =IFERROR(LOOKUP(2,1/((Interaction_Log!$B$2:$B$3000=$A11)*(Interaction_Log!$G$2:$G$3000<>"")),Interaction_Log!$G$2:$G$3000),"") -> 46248 | F11: =IFERROR(INDEX(Lists!$C$2:$C$12,MATCH($C11,Lists!$A$2:$A$12,0)),"") -> Medium | G11: =IFERROR(INDEX(Lists!$D$2:$D$12,MATCH($C11,Lists!$A$2:$A$12,0)),"") -> Call | H11: =IF(OR($D11="Converted",$D11="Closed"),"—",IF($E11="","Not Scheduled",IF($E11<CRM_Dashboard!$B$3,"Overdue",IF($E11=CRM_Dashboard!$B$3,"Due Today","Upcoming")))) -> Overdue | I11: =COUNTIF(Interaction_Log!$B$2:$B$3000,$A11) -> 1 | J11: =IF(COUNTIFS(Interaction_Log!$B$2:$B$3000,$A11,Interaction_Log!$E$2:$E$3000,"Details Sent")>0,"Yes","No") -> No | K11: =IF(AND(COUNTIFS(Interaction_Log!$B$2:$B$3000,$A11,Interaction_Log!$E$2:$E$3000,"Paid")>0,$C11<>"Paid"),"Paid then re-opened","")
A12: LEAD0011 | B12: =IFERROR(INDEX(Lead_Master!$B$2:$B$1000,MATCH($A12,Lead_Master!$A$2:$A$1000,0)),"") -> Mehak Jain | C12: =IFERROR(LOOKUP(2,1/(Interaction_Log!$B$2:$B$3000=$A12),Interaction_Log!$E$2:$E$3000),"No contact") -> Not Interested | D12: =IFERROR(INDEX(Lists!$B$2:$B$12,MATCH($C12,Lists!$A$2:$A$12,0)),"Unmapped") -> Closed | E12: =IFERROR(LOOKUP(2,1/((Interaction_Log!$B$2:$B$3000=$A12)*(Interaction_Log!$G$2:$G$3000<>"")),Interaction_Log!$G$2:$G$3000),"") | F12: =IFERROR(INDEX(Lists!$C$2:$C$12,MATCH($C12,Lists!$A$2:$A$12,0)),"") -> — | G12: =IFERROR(INDEX(Lists!$D$2:$D$12,MATCH($C12,Lists!$A$2:$A$12,0)),"") -> No action | H12: =IF(OR($D12="Converted",$D12="Closed"),"—",IF($E12="","Not Scheduled",IF($E12<CRM_Dashboard!$B$3,"Overdue",IF($E12=CRM_Dashboard!$B$3,"Due Today","Upcoming")))) -> — | I12: =COUNTIF(Interaction_Log!$B$2:$B$3000,$A12) -> 2 | J12: =IF(COUNTIFS(Interaction_Log!$B$2:$B$3000,$A12,Interaction_Log!$E$2:$E$3000,"Details Sent")>0,"Yes","No") -> No | K12: =IF(AND(COUNTIFS(Interaction_Log!$B$2:$B$3000,$A12,Interaction_Log!$E$2:$E$3000,"Paid")>0,$C12<>"Paid"),"Paid then re-opened","")
A13: LEAD0012 | B13: =IFERROR(INDEX(Lead_Master!$B$2:$B$1000,MATCH($A13,Lead_Master!$A$2:$A$1000,0)),"") -> Harsh Patel | C13: =IFERROR(LOOKUP(2,1/(Interaction_Log!$B$2:$B$3000=$A13),Interaction_Log!$E$2:$E$3000),"No contact") -> Switch Off | D13: =IFERROR(INDEX(Lists!$B$2:$B$12,MATCH($C13,Lists!$A$2:$A$12,0)),"Unmapped") -> Pending | E13: =IFERROR(LOOKUP(2,1/((Interaction_Log!$B$2:$B$3000=$A13)*(Interaction_Log!$G$2:$G$3000<>"")),Interaction_Log!$G$2:$G$3000),"") | F13: =IFERROR(INDEX(Lists!$C$2:$C$12,MATCH($C13,Lists!$A$2:$A$12,0)),"") -> Low | G13: =IFERROR(INDEX(Lists!$D$2:$D$12,MATCH($C13,Lists!$A$2:$A$12,0)),"") -> Retry | H13: =IF(OR($D13="Converted",$D13="Closed"),"—",IF($E13="","Not Scheduled",IF($E13<CRM_Dashboard!$B$3,"Overdue",IF($E13=CRM_Dashboard!$B$3,"Due Today","Upcoming")))) -> Not Scheduled | I13: =COUNTIF(Interaction_Log!$B$2:$B$3000,$A13) -> 2 | J13: =IF(COUNTIFS(Interaction_Log!$B$2:$B$3000,$A13,Interaction_Log!$E$2:$E$3000,"Details Sent")>0,"Yes","No") -> No | K13: =IF(AND(COUNTIFS(Interaction_Log!$B$2:$B$3000,$A13,Interaction_Log!$E$2:$E$3000,"Paid")>0,$C13<>"Paid"),"Paid then re-opened","")
... A301: LEAD0300 | B301: =IFERROR(INDEX(Lead_Master!$B$2:$B$1000,MATCH($A301,Lead_Master!$A$2:$A$1000,0)),"") -> Ananya Rathore | C301: =IFERROR(LOOKUP(2,1/(Interaction_Log!$B$2:$B$3000=$A301),Interaction_Log!$E$2:$E$3000),"No contact") -> DNP | D301: =IFERROR(INDEX(Lists!$B$2:$B$12,MATCH($C301,Lists!$A$2:$A$12,0)),"Unmapped") -> Pending | E301: =IFERROR(LOOKUP(2,1/((Interaction_Log!$B$2:$B$3000=$A301)*(Interaction_Log!$G$2:$G$3000<>"")),Interaction_Log!$G$2:$G$3000),"") | F301: =IFERROR(INDEX(Lists!$C$2:$C$12,MATCH($C301,Lists!$A$2:$A$12,0)),"") -> Low | G301: =IFERROR(INDEX(Lists!$D$2:$D$12,MATCH($C301,Lists!$A$2:$A$12,0)),"") -> Retry | H301: =IF(OR($D301="Converted",$D301="Closed"),"—",IF($E301="","Not Scheduled",IF($E301<CRM_Dashboard!$B$3,"Overdue",IF($E301=CRM_Dashboard!$B$3,"Due Today","Upcoming")))) -> Not Scheduled | I301: =COUNTIF(Interaction_Log!$B$2:$B$3000,$A301) -> 4 | J301: =IF(COUNTIFS(Interaction_Log!$B$2:$B$3000,$A301,Interaction_Log!$E$2:$E$3000,"Details Sent")>0,"Yes","No") -> No | K301: =IF(AND(COUNTIFS(Interaction_Log!$B$2:$B$3000,$A301,Interaction_Log!$E$2:$E$3000,"Paid")>0,$C301<>"Paid"),"Paid then re-opened","")

Sheet CRM_Dashboard
A1: CRM-Style Lead & Customer Interaction Tracker — Dashboard
A3: As-of date | B3: 46294 | C3: ← input (set to =TODAY() for live use). Drives Overdue / Due Today flags and the Data Check column.
A5: TOTAL LEADS | B5: CONTACTED | D5: FOLLOW-UPS SCHEDULED | F5: DETAILS SENT | H5: CONVERTED / PAID | J5: CONVERSION RATE | L5: OVERDUE FOLLOW-UPS
A6: =COUNTA(Lead_Master!$A$2:$A$1000) -> 300 | B6: =COUNTIF(Follow_Up_Tracker!$I$2:$I$1000,">0") -> 300 | D6: =COUNT(Follow_Up_Tracker!$E$2:$E$1000) -> 126 | F6: =COUNTIF(Follow_Up_Tracker!$J$2:$J$1000,"Yes") -> 114 | H6: =COUNTIF(Follow_Up_Tracker!$C$2:$C$1000,"Paid") -> 24 | J6: =IFERROR(H6/A6,0) -> 0.08 | L6: =COUNTIF(Follow_Up_Tracker!$H$2:$H$1000,"Overdue") -> 119
A8: Contacted = leads with ≥1 logged interaction · Follow-ups Scheduled = leads with a next follow-up date · Details Sent = leads with ≥1 "Details Sent" interaction · Converted = latest outcome is Paid · Overdue = open lead whose follow-up date is before the as-of date.
A10: 1. Lead Status (latest outcome per lead)
A11: Category | B11: Count | C11: % Share
A12: DNP | B12: =COUNTIF(Follow_Up_Tracker!$C$2:$C$1000,$A12) -> 77 | C12: =IFERROR(B12/SUM($B$12:$B$22),0) -> 0.25666667
A13: Details Sent | B13: =COUNTIF(Follow_Up_Tracker!$C$2:$C$1000,$A13) -> 49 | C13: =IFERROR(B13/SUM($B$12:$B$22),0) -> 0.16333333
A14: Follow Up | B14: =COUNTIF(Follow_Up_Tracker!$C$2:$C$1000,$A14) -> 41 | C14: =IFERROR(B14/SUM($B$12:$B$22),0) -> 0.13666667
A15: Call Back Later | B15: =COUNTIF(Follow_Up_Tracker!$C$2:$C$1000,$A15) -> 33 | C15: =IFERROR(B15/SUM($B$12:$B$22),0) -> 0.11
A16: Paid | B16: =COUNTIF(Follow_Up_Tracker!$C$2:$C$1000,$A16) -> 24 | C16: =IFERROR(B16/SUM($B$12:$B$22),0) -> 0.08
A17: Not Interested | B17: =COUNTIF(Follow_Up_Tracker!$C$2:$C$1000,$A17) -> 24 | C17: =IFERROR(B17/SUM($B$12:$B$22),0) -> 0.08
A18: Switch Off | B18: =COUNTIF(Follow_Up_Tracker!$C$2:$C$1000,$A18) -> 17 | C18: =IFERROR(B18/SUM($B$12:$B$22),0) -> 0.056666667
A19: Not Reachable | B19: =COUNTIF(Follow_Up_Tracker!$C$2:$C$1000,$A19) -> 15 | C19: =IFERROR(B19/SUM($B$12:$B$22),0) -> 0.05
A20: Wrong Number | B20: =COUNTIF(Follow_Up_Tracker!$C$2:$C$1000,$A20) -> 9 | C20: =IFERROR(B20/SUM($B$12:$B$22),0) -> 0.03
A21: Call Cut | B21: =COUNTIF(Follow_Up_Tracker!$C$2:$C$1000,$A21) -> 8 | C21: =IFERROR(B21/SUM($B$12:$B$22),0) -> 0.026666667
A22: Message Sent | B22: =COUNTIF(Follow_Up_Tracker!$C$2:$C$1000,$A22) -> 3 | C22: =IFERROR(B22/SUM($B$12:$B$22),0) -> 0.01
A23: Total | B23: =SUM(B12:B22) -> 300
A27: 2. Interested Program
A28: Category | B28: Count | C28: % Share
A29: Cloud Computing | B29: =COUNTIF(Lead_Master!$H$2:$H$1000,$A29) -> 53 | C29: =IFERROR(B29/SUM($B$29:$B$35),0) -> 0.17666667
A30: Business Analytics | B30: =COUNTIF(Lead_Master!$H$2:$H$1000,$A30) -> 48 | C30: =IFERROR(B30/SUM($B$29:$B$35),0) -> 0.16
A31: Full Stack Development | B31: =COUNTIF(Lead_Master!$H$2:$H$1000,$A31) -> 43 | C31: =IFERROR(B31/SUM($B$29:$B$35),0) -> 0.14333333
A32: Data Analytics | B32: =COUNTIF(Lead_Master!$H$2:$H$1000,$A32) -> 42 | C32: =IFERROR(B32/SUM($B$29:$B$35),0) -> 0.14
A33: Cyber Security | B33: =COUNTIF(Lead_Master!$H$2:$H$1000,$A33) -> 40 | C33: =IFERROR(B33/SUM($B$29:$B$35),0) -> 0.13333333
A34: AI & Machine Learning | B34: =COUNTIF(Lead_Master!$H$2:$H$1000,$A34) -> 38 | C34: =IFERROR(B34/SUM($B$29:$B$35),0) -> 0.12666667
A35: Digital Marketing | B35: =COUNTIF(Lead_Master!$H$2:$H$1000,$A35) -> 36 | C35: =IFERROR(B35/SUM($B$29:$B$35),0) -> 0.12
A36: Total | B36: =SUM(B29:B35) -> 300
A44: 3. Interaction Outcome (all logged interactions)
A45: Category | B45: Count | C45: % Share
A46: DNP | B46: =COUNTIF(Interaction_Log!$E$2:$E$3000,$A46) -> 201 | C46: =IFERROR(B46/SUM($B$46:$B$56),0) -> 0.26907631
A47: Details Sent | B47: =COUNTIF(Interaction_Log!$E$2:$E$3000,$A47) -> 139 | C47: =IFERROR(B47/SUM($B$46:$B$56),0) -> 0.18607764
A48: Follow Up | B48: =COUNTIF(Interaction_Log!$E$2:$E$3000,$A48) -> 95 | C48: =IFERROR(B48/SUM($B$46:$B$56),0) -> 0.12717537
A49: Call Back Later | B49: =COUNTIF(Interaction_Log!$E$2:$E$3000,$A49) -> 83 | C49: =IFERROR(B49/SUM($B$46:$B$56),0) -> 0.11111111
A50: Not Interested | B50: =COUNTIF(Interaction_Log!$E$2:$E$3000,$A50) -> 67 | C50: =IFERROR(B50/SUM($B$46:$B$56),0) -> 0.089692102
A51: Not Reachable | B51: =COUNTIF(Interaction_Log!$E$2:$E$3000,$A51) -> 40 | C51: =IFERROR(B51/SUM($B$46:$B$56),0) -> 0.053547523
A52: Paid | B52: =COUNTIF(Interaction_Log!$E$2:$E$3000,$A52) -> 39 | C52: =IFERROR(B52/SUM($B$46:$B$56),0) -> 0.052208835
A53: Switch Off | B53: =COUNTIF(Interaction_Log!$E$2:$E$3000,$A53) -> 33 | C53: =IFERROR(B53/SUM($B$46:$B$56),0) -> 0.044176707
A54: Call Cut | B54: =COUNTIF(Interaction_Log!$E$2:$E$3000,$A54) -> 22 | C54: =IFERROR(B54/SUM($B$46:$B$56),0) -> 0.029451138
...

Sheet Lists
A1: Outcome | B1: Current Status | C1: Priority | D1: Action | F1: Status map: edit the blue cells to change how each outcome is classified, prioritised and actioned. Follow_Up_Tracker reads this table.
A2: Details Sent | B2: Follow Up | C2: High | D2: Call
A3: Follow Up | B3: Follow Up | C3: High | D3: Call
A4: Message Sent | B4: Follow Up | C4: Medium | D4: Call
A5: Call Back Later | B5: Pending | C5: Medium | D5: Call
A6: Call Cut | B6: Pending | C6: Medium | D6: Retry
A7: DNP | B7: Pending | C7: Low | D7: Retry
A8: Switch Off | B8: Pending | C8: Low | D8: Retry
A9: Not Reachable | B9: Pending | C9: Low | D9: Retry
A10: Paid | B10: Converted | C10: — | D10: Onboard
A11: Not Interested | B11: Closed | C11: — | D11: No action
A12: Wrong Number | B12: Closed | C12: — | D12: Verify number

Sheet Notes_DataQuality
A1: Notes, Assumptions & Data-Quality Checks
A3: DATA: 300 synthetic leads and 747 interactions (names, e-mails on example.com, phones are generated — safe for a public repo). Source: BDA_Lead_Followup_Dataset.xlsx (the "(1)" copy and the CSV hold identical data).
A4: HOW IT WORKS: Interaction_Log is the single source of truth. Follow_Up_Tracker and CRM_Dashboard are formulas that read it; nothing on them is typed in except the Lead IDs.
A5: LEGEND: blue text = editable input (Lists status map, as-of date). Yellow cell = as-of date. Black = raw data or formula.
A6: ASSUMPTION — Interaction Type: the source has no type field. "Message Sent" outcomes are typed Message; everything else is typed Call.
A7: ASSUMPTION — Next Follow-up: the source holds one follow-up date per lead. It is placed on that lead's last interaction row; other rows are blank.
A8: ASSUMPTION — Status map (Lists sheet): Current Status / Priority / Action per outcome are my proposed defaults, not from the source. Edit them in Lists.
A9: ADDING DATA: append rows to Interaction_Log (keep rows of one lead together, in order) and copy the last Follow_Up_Tracker row down for new leads. Formulas cover up to row 3000 (log) and 1000 (leads).
A10: CLEANING DONE: outcome names standardised to Title Case (DNP kept upper-case); phone stored as text; dates converted to real dates; Interaction_History in the source verified against the log (all 300 leads match in order).
A12: Check | B12: Result | C12: Status | D12: Finding / treatment
A13: Duplicate Lead IDs | B13: =SUMPRODUCT(--(COUNTIF(Lead_Master!$A$2:$A$301,Lead_Master!$A$2:$A$301)>1)) -> 0 | C13: =IF(B13=0,"OK","Review") -> OK | D13: None found.
A14: Duplicate e-mails | B14: =SUMPRODUCT(--(COUNTIF(Lead_Master!$C$2:$C$301,Lead_Master!$C$2:$C$301)>1)) -> 0 | C14: =IF(B14=0,"OK","Review") -> OK | D14: None found.
A15: Duplicate phone numbers | B15: =SUMPRODUCT(--(COUNTIF(Lead_Master!$D$2:$D$301,Lead_Master!$D$2:$D$301)>1)) -> 0 | C15: =IF(B15=0,"OK","Review") -> OK | D15: None found.
A16: E-mails missing "@" | B16: =SUMPRODUCT(--ISERROR(FIND("@",Lead_Master!$C$2:$C$301))) -> 0 | C16: =IF(B16=0,"OK","Review") -> OK | D16: Basic format check.
A17: Phone numbers not 10 digits | B17: =SUMPRODUCT(--(LEN(Lead_Master!$D$2:$D$301)<>10)) -> 0 | C17: =IF(B17=0,"OK","Review") -> OK | D17: All stored as 10-digit text.
A18: Blank cells in Lead_Master | B18: =COUNTBLANK(Lead_Master!$A$2:$J$301) -> 0 | C18: =IF(B18=0,"OK","Review") -> OK | D18: No N/A / blank entries in this dataset.
A19: Leads sharing a name with another lead | B19: =SUMPRODUCT(--(COUNTIF(Lead_Master!$B$2:$B$301,Lead_Master!$B$2:$B$301)>1)) -> 154 | C19: =IF(B19=0,"OK","Review") -> Review | D19: Info only: different e-mail and phone, so treated as different people, not duplicates.
A20: Interactions with unknown Lead ID | B20: =SUMPRODUCT(--(COUNTIF(Lead_Master!$A$2:$A$301,Interaction_Log!$B$2:$B$748)=0)) -> 0 | C20: =IF(B20=0,"OK","Review") -> OK | D20: None found.
A21: Leads with no interaction | B21: =COUNTIF(Follow_Up_Tracker!$I$2:$I$301,0) -> 0 | C21: =IF(B21=0,"OK","Review") -> OK | D21: All leads contacted at least once.
A22: Interactions dated after the as-of date | B22: =COUNTIF(Interaction_Log!$H$2:$H$748,"Future-dated") -> 17 | C22: =IF(B22=0,"OK","Review") -> Review | D22: Kept as-is and flagged in Interaction_Log column H — confirm whether these are planned calls or typos.
A23: Interaction dates out of sequence within a lead | B23: =COUNTIF(Interaction_Log!$H$2:$H$748,"Date out of sequence") -> 144 | C23: =IF(B23=0,"OK","Review") -> Review | D23: Outcome order matches the source history, but the date is earlier than the previous row. Kept as-is and flagged.
A24: Follow-up date not after the interaction | B24: =COUNTIF(Interaction_Log!$H$2:$H$748,"Follow-up not after interaction") -> 38 | C24: =IF(B24=0,"OK","Review") -> Review | D24: Follow-up date on/before the last interaction date. Kept as-is and flagged.
A25: Leads marked Paid earlier, but latest outcome is not Paid | B25: =COUNTIF(Follow_Up_Tracker!$K$2:$K$301,"Paid then re-opened") -> 15 | C25: =IF(B25=0,"OK","Review") -> Review | D25: Latest outcome drives status, so these are NOT counted as Converted. Verify with the sales owner.
A26: Open leads with no follow-up date | B26: =COUNTIF(Follow_Up_Tracker!$H$2:$H$301,"Not Scheduled") -> 117 | C26: =IF(B26=0,"OK","Review") -> Review | D26: Follow Up / Pending leads with no next-follow-up date — schedule these.
